<?xml version="1.0" encoding="utf-8"?>
<!-- This URDF was automatically created by SolidWorks to URDF Exporter! Originally created by Stephen Brawner (brawner@gmail.com) 
     Commit Version: 1.6.0-4-g7f85cfe  Build Version: 1.6.7995.38578
     For more information, please see http://wiki.ros.org/sw_urdf_exporter -->
<robot
  name="Assem1">
  <link
    name="base_link">
    <inertial>
      <origin
        xyz="0.0686960819979954 0.0906663823430862 0.128057388312242"
        rpy="0 0 0" />
      <mass
        value="0.366135832063462" />
      <inertia
        ixx="0.000335468988355107"
        ixy="-1.37556999741366E-07"
        ixz="-3.91168233468655E-07"
        iyy="0.000595094796888886"
        iyz="-7.17626466054021E-08"
        izz="0.000278806379023775" />
    </inertial>
    <visual>
      <origin
        xyz="0 0 0"
        rpy="0 0 0" />
      <geometry>
        <mesh
          filename="package://Assem1/meshes/base_link.STL" />
      </geometry>
      <material
        name="">
        <color
          rgba="0.792156862745098 0.819607843137255 0.933333333333333 1" />
      </material>
    </visual>
    <collision>
      <origin
        xyz="0 0 0"
        rpy="0 0 0" />
      <geometry>
        <mesh
          filename="package://Assem1/meshes/base_link.STL" />
      </geometry>
    </collision>
  </link>
  <link
    name="liadr_link">
    <inertial>
      <origin
        xyz="0.0267059004296605 0.0250000000000024 -0.0377011422227911"
        rpy="0 0 0" />
      <mass
        value="0.146695752131392" />
      <inertia
        ixx="6.22721120792819E-05"
        ixy="-2.39760403490095E-19"
        ixz="1.88658076337422E-05"
        iyy="0.000109673997590948"
        iyz="-4.04119502993067E-19"
        izz="0.000125682524275729" />
    </inertial>
    <visual>
      <origin
        xyz="0 0 0"
        rpy="0 0 0" />
      <geometry>
        <mesh
          filename="package://Assem1/meshes/liadr_link.STL" />
      </geometry>
      <material
        name="">
        <color
          rgba="0.792156862745098 0.819607843137255 0.933333333333333 1" />
      </material>
    </visual>
    <collision>
      <origin
        xyz="0 0 0"
        rpy="0 0 0" />
      <geometry>
        <mesh
          filename="package://Assem1/meshes/liadr_link.STL" />
      </geometry>
    </collision>
  </link>
  <joint
    name="ydlidar"
    type="fixed">
    <origin
      xyz="0.042231 -0.15118 0.16236"
      rpy="3.1416 0 1.5708" />
    <parent
      link="base_link" />
    <child
      link="liadr_link" />
    <axis
      xyz="0 0 1" />
  </joint>
  <link
    name="imu_link">
    <inertial>
      <origin
        xyz="-1.16573417585641E-15 -1.67921232474555E-15 -0.00525465003429967"
        rpy="0 0 0" />
      <mass
        value="0.0259119734073464" />
      <inertia
        ixx="4.88469120518662E-06"
        ixy="-5.77187056134516E-22"
        ixz="7.74475741301589E-21"
        iyy="5.92754134098662E-06"
        iyz="-1.07880896915291E-21"
        izz="1.0222025489862E-05" />
    </inertial>
    <visual>
      <origin
        xyz="0 0 0"
        rpy="0 0 0" />
      <geometry>
        <mesh
          filename="package://Assem1/meshes/imu_link.STL" />
      </geometry>
      <material
        name="">
        <color
          rgba="1 1 1 1" />
      </material>
    </visual>
    <collision>
      <origin
        xyz="0 0 0"
        rpy="0 0 0" />
      <geometry>
        <mesh
          filename="package://Assem1/meshes/imu_link.STL" />
      </geometry>
    </collision>
  </link>
  <joint
    name="imu_joint"
    type="fixed">
    <origin
      xyz="0.067231 -0.12268 0.16236"
      rpy="3.1416 0 -3.1416" />
    <parent
      link="base_link" />
    <child
      link="imu_link" />
    <axis
      xyz="0 0 1" />
  </joint>
  <link
    name="right_wheel">
    <inertial>
      <origin
        xyz="0.0175974886707705 4.34781335933998E-10 1.2462056941942E-09"
        rpy="0 0 0" />
      <mass
        value="0.0236172986040457" />
      <inertia
        ixx="2.01293821963848E-05"
        ixy="-3.20838844082092E-14"
        ixz="1.1181926193534E-13"
        iyy="1.18496952116128E-05"
        iyz="-4.65783459380596E-10"
        izz="1.18493501822185E-05" />
    </inertial>
    <visual>
      <origin
        xyz="0 0 0"
        rpy="0 0 0" />
      <geometry>
        <mesh
          filename="package://Assem1/meshes/right_wheel.STL" />
      </geometry>
      <material
        name="">
        <color
          rgba="0.333333333333333 0.333333333333333 0.333333333333333 1" />
      </material>
    </visual>
    <collision>
      <origin
        xyz="0 0 0"
        rpy="0 0 0" />
      <geometry>
        <mesh
          filename="package://Assem1/meshes/right_wheel.STL" />
      </geometry>
    </collision>
  </link>
  <joint
    name="right_joint"
    type="continuous">
    <origin
      xyz="0.13736 -0.18018 0.057855"
      rpy="1.944 0 0" />
    <parent
      link="base_link" />
    <child
      link="right_wheel" />
    <axis
      xyz="1 0 0" />
  </joint>
  <link
    name="left_wheel">
    <inertial>
      <origin
        xyz="0.017597488518994 4.06901727589837E-10 1.01868818935813E-09"
        rpy="0 0 0" />
      <mass
        value="0.0236172977847739" />
      <inertia
        ixx="2.0129381628138E-05"
        ixy="-2.94867891164861E-14"
        ixz="1.33213461826757E-13"
        iyy="1.18496951518561E-05"
        iyz="-4.65842569565079E-10"
        izz="1.18493496501115E-05" />
    </inertial>
    <visual>
      <origin
        xyz="0 0 0"
        rpy="0 0 0" />
      <geometry>
        <mesh
          filename="package://Assem1/meshes/left_wheel.STL" />
      </geometry>
      <material
        name="">
        <color
          rgba="0.333333333333333 0.333333333333333 0.333333333333333 1" />
      </material>
    </visual>
    <collision>
      <origin
        xyz="0 0 0"
        rpy="0 0 0" />
      <geometry>
        <mesh
          filename="package://Assem1/meshes/left_wheel.STL" />
      </geometry>
    </collision>
  </link>
  <joint
    name="left_joint"
    type="continuous">
    <origin
      xyz="-0.0027026 -0.18018 0.057855"
      rpy="1.7016 0 -3.1416" />
    <parent
      link="base_link" />
    <child
      link="left_wheel" />
    <axis
      xyz="1 0 0" />
  </joint>
  <link
    name="caster_link">
    <inertial>
      <origin
        xyz="-9.36750677027476E-17 -0.008 2.08166817117217E-16"
        rpy="0 0 0" />
      <mass
        value="0.00750671516206051" />
      <inertia
        ixx="4.62655708309704E-07"
        ixy="2.93257616962947E-24"
        ixz="0"
        iyy="6.07617317877851E-07"
        iyz="7.0379463032345E-24"
        izz="4.62655708309704E-07" />
    </inertial>
    <visual>
      <origin
        xyz="0 0 0"
        rpy="0 0 0" />
      <geometry>
        <mesh
          filename="package://Assem1/meshes/caster_link.STL" />
      </geometry>
      <material
        name="">
        <color
          rgba="0.792156862745098 0.819607843137255 0.933333333333333 1" />
      </material>
    </visual>
    <collision>
      <origin
        xyz="0 0 0"
        rpy="0 0 0" />
      <geometry>
        <mesh
          filename="package://Assem1/meshes/caster_link.STL" />
      </geometry>
    </collision>
  </link>
  <joint
    name="caster_joint"
    type="continuous">
    <origin
      xyz="0.058231 -0.052185 0.036355"
      rpy="3.1416 1.3388 -1.5708" />
    <parent
      link="base_link" />
    <child
      link="caster_link" />
    <axis
      xyz="0 1 0" />
  </joint>
</robot>