<?xml version="1.0" encoding="utf-8"?>
<!-- This URDF was automatically created by SolidWorks to URDF Exporter! Originally created by Stephen Brawner (brawner@gmail.com) 
     Commit Version: 1.6.0-4-g7f85cfe  Build Version: 1.6.7995.38578
     For more information, please see http://wiki.ros.org/sw_urdf_exporter -->
<robot
  name="sr_robot">
  <link
    name="base_link">
    <inertial>
      <origin
        xyz="0.0686960819979955 -0.128057388312242 0.0906663823430837"
        rpy="0 0 0" />
      <mass
        value="0.366135832063462" />
      <inertia
        ixx="0.000335468988355107"
        ixy="3.91168233468665E-07"
        ixz="-1.37556999741366E-07"
        iyy="0.000278806379023775"
        iyz="7.17626466054311E-08"
        izz="0.000595094796888886" />
    </inertial>
    <visual>
      <origin
        xyz="0 0 0"
        rpy="0 0 0" />
      <geometry>
        <mesh
          filename="package://sr_robot/meshes/base_link.STL" />
      </geometry>
      <material
        name="">
        <color
          rgba="0.792156862745098 0.819607843137255 0.933333333333333 1" />
      </material>
    </visual>
    <collision>
      <origin
        xyz="0 0 0"
        rpy="0 0 0" />
      <geometry>
        <mesh
          filename="package://sr_robot/meshes/base_link.STL" />
      </geometry>
    </collision>
  </link>
  <link
    name="liadr_link">
    <inertial>
      <origin
        xyz="0.026706 0.025 -0.037701"
        rpy="0 0 0" />
      <mass
        value="0.1467" />
      <inertia
        ixx="6.2272E-05"
        ixy="-2.3988E-19"
        ixz="1.8866E-05"
        iyy="0.00010967"
        iyz="-4.041E-19"
        izz="0.00012568" />
    </inertial>
    <visual>
      <origin
        xyz="0 0 0"
        rpy="0 0 0" />
      <geometry>
        <mesh
          filename="package://sr_robot/meshes/liadr_link.STL" />
      </geometry>
      <material
        name="">
        <color
          rgba="0.79216 0.81961 0.93333 1" />
      </material>
    </visual>
    <collision>
      <origin
        xyz="0 0 0"
        rpy="0 0 0" />
      <geometry>
        <mesh
          filename="package://sr_robot/meshes/liadr_link.STL" />
      </geometry>
    </collision>
  </link>
  <joint
    name="ydlidar"
    type="fixed">
    <origin
      xyz="0.042231 -0.15118 0.16236"
      rpy="3.1416 0 1.5708" />
    <parent
      link="base_link" />
    <child
      link="liadr_link" />
    <axis
      xyz="0 0 0" />
  </joint>
  <link
    name="imu_link">
    <inertial>
      <origin
        xyz="-1.1657E-15 -1.6792E-15 -0.0052547"
        rpy="0 0 0" />
      <mass
        value="0.025912" />
      <inertia
        ixx="4.8847E-06"
        ixy="-4.0174E-22"
        ixz="7.7935E-21"
        iyy="5.9275E-06"
        iyz="-1.0843E-21"
        izz="1.0222E-05" />
    </inertial>
    <visual>
      <origin
        xyz="0 0 0"
        rpy="0 0 0" />
      <geometry>
        <mesh
          filename="package://sr_robot/meshes/imu_link.STL" />
      </geometry>
      <material
        name="">
        <color
          rgba="1 1 1 1" />
      </material>
    </visual>
    <collision>
      <origin
        xyz="0 0 0"
        rpy="0 0 0" />
      <geometry>
        <mesh
          filename="package://sr_robot/meshes/imu_link.STL" />
      </geometry>
    </collision>
  </link>
  <joint
    name="imu_joint"
    type="fixed">
    <origin
      xyz="0.067231 -0.12268 0.16236"
      rpy="3.1416 0 -3.1416" />
    <parent
      link="base_link" />
    <child
      link="imu_link" />
    <axis
      xyz="0 0 0" />
  </joint>
  <link
    name="right_wheel">
    <inertial>
      <origin
        xyz="0.018914 1.0267E-09 8.2821E-10"
        rpy="0 0 0" />
      <mass
        value="0.023617" />
      <inertia
        ixx="2.0129E-05"
        ixy="3.2098E-14"
        ixz="1.1178E-13"
        iyy="1.1849E-05"
        iyz="-3.5994E-10"
        izz="1.185E-05" />
    </inertial>
    <visual>
      <origin
        xyz="0 0 0"
        rpy="0 0 0" />
      <geometry>
        <mesh
          filename="package://sr_robot/meshes/right_wheel.STL" />
      </geometry>
      <material
        name="">
        <color
          rgba="0.33333 0.33333 0.33333 1" />
      </material>
    </visual>
    <collision>
      <origin
        xyz="0 0 0"
        rpy="0 0 0" />
      <geometry>
        <mesh
          filename="package://sr_robot/meshes/right_wheel.STL" />
      </geometry>
    </collision>
  </link>
  <joint
    name="right_joint"
    type="continuous">
    <origin
      xyz="0.13736 -0.18018 0.057855"
      rpy="1.944 0 0" />
    <parent
      link="base_link" />
    <child
      link="right_wheel" />
    <axis
      xyz="1 0 0" />
  </joint>
  <link
    name="left_wheel">
    <inertial>
      <origin
        xyz="0.017597 4.069E-10 1.0187E-09"
        rpy="0 0 0" />
      <mass
        value="0.023617" />
      <inertia
        ixx="2.0129E-05"
        ixy="-2.9487E-14"
        ixz="1.3321E-13"
        iyy="1.185E-05"
        iyz="-4.6584E-10"
        izz="1.1849E-05" />
    </inertial>
    <visual>
      <origin
        xyz="0 0 0"
        rpy="0 0 0" />
      <geometry>
        <mesh
          filename="package://sr_robot/meshes/left_wheel.STL" />
      </geometry>
      <material
        name="">
        <color
          rgba="0.33333 0.33333 0.33333 1" />
      </material>
    </visual>
    <collision>
      <origin
        xyz="0 0 0"
        rpy="0 0 0" />
      <geometry>
        <mesh
          filename="package://sr_robot/meshes/left_wheel.STL" />
      </geometry>
    </collision>
  </link>
  <joint
    name="left_joint"
    type="continuous">
    <origin
      xyz="-0.0027026 -0.18018 0.057855"
      rpy="1.7016 0 -3.1416" />
    <parent
      link="base_link" />
    <child
      link="left_wheel" />
    <axis
      xyz="1 0 0" />
  </joint>
  <link
    name="caster_link">
    <inertial>
      <origin
        xyz="-9.3675E-17 -0.008 2.0817E-16"
        rpy="0 0 0" />
      <mass
        value="0.0075067" />
      <inertia
        ixx="4.6266E-07"
        ixy="2.9326E-24"
        ixz="0"
        iyy="6.0762E-07"
        iyz="7.0379E-24"
        izz="4.6266E-07" />
    </inertial>
    <visual>
      <origin
        xyz="0 0 0"
        rpy="0 0 0" />
      <geometry>
        <mesh
          filename="package://sr_robot/meshes/caster_link.STL" />
      </geometry>
      <material
        name="">
        <color
          rgba="0.79216 0.81961 0.93333 1" />
      </material>
    </visual>
    <collision>
      <origin
        xyz="0 0 0"
        rpy="0 0 0" />
      <geometry>
        <mesh
          filename="package://sr_robot/meshes/caster_link.STL" />
      </geometry>
    </collision>
  </link>
  <joint
    name="caster_joint"
    type="continuous">
    <origin
      xyz="0.058231 -0.052185 0.036355"
      rpy="3.1416 1.3388 -1.5708" />
    <parent
      link="base_link" />
    <child
      link="caster_link" />
    <axis
      xyz="0 1 0" />
  </joint>
</robot>